Workbook

Sheet Info
A1: Statsfinity – Deckbuilding benchmarks
A3: This sheet comes from the Statsfinity community: two players used it to optimize their Commander decks.
A4: Statsfinity's deck check takes the ranges and play styles from it (sheet “Benchmarks by Card Role”):
A5: Lands 29–37 · Ramp 9–17 · Card draw 7–15 · Single target removal 7–15 · Board wipes 0–8 · Win cons ~3 (±3).
A6: The target starts in the middle of each range; every matching play style moves it a quarter of the range towards “fewer” or “more”.
A7: Statsfinity reads the curve (low/high) from the average mana value: up to 2.8 low, from 3.6 high.
A8: Double-faced cards with a land back: count 1:1 if the land can enter untapped (e.g. pay 3 life), otherwise 0.38 (Frank Karsten).
A10: The probabilities (“At least 1 by turn X”) are hypergeometric; the sheet “Hypergeometric Calculator” computes any case of your own.

Sheet Hypergeometric Calculator
A1: Parameter | B1: Description | C1: Value | E1: Results (percent)
A2: Cards in deck | B2: 99 normally | C2: 99 | E2: Exactly 0 | F2: =Data!B1*100 -> 22.728232
A3: Cards drawn | B3: Depends on the turn | C3: 10 | E3: Exactly 1 | F3: =Data!B2*100 -> 38.37234 | H3: At least 1 | I3: =SUM(F3:F7) -> 77.24722 | K3: At most 1 | L3: =100-I3 -> 22.75278
A4: Hits in deck | B4: How many cards in the deck are the right ones | C4: 13 | E4: Exactly 2 | F4: =Data!B3*100 -> 26.565466 | H4: At least 2 | I4: =SUM(F4:F7) -> 38.87488 | K4: At most 2 | L4: =100-I4 -> 61.12512
E5: Exactly 3 | F5: =Data!B4*100 -> 9.8639706 | H5: At least 3 | I5: =SUM(F5:F7) -> 12.309413 | K5: At most 3 | L5: =100-I5 -> 87.690587
E6: Exactly 4 | F6: =Data!B5*100 -> 2.1577436 | H6: At least 4 | I6: =SUM(F6:F7) -> 2.4454427 | K6: At most 4 | L6: =100-I6 -> 97.554557
E7: Exactly 5 | F7: =Data!B6*100 -> 0.28769914 | H7: At least 5 | I7: =SUM(F7:F7) -> 0.28769914 | K7: At most 5 | L7: =100-I7 -> 99.712301

Sheet Benchmarks by Card Role
A1: Turn | C1: Deck types | D1: Lands | M1: Deck types | O1: Turn | P1: Notes
C2: Fast Mana | D2: 29 | E2: 30 | F2: 31 | G2: 32 | H2: 33 | I2: 34 | J2: 35 | K2: 36 | L2: 37 | M2: Landfall | P2: More untapped lands = better MDFC lands replace lands 1:1 (max. 5 or 6 because they are slow)
B3: At least 1 by turn X | C3: Low curve | D3: Average number drawn | M3: High curve | N3: At least 1 by turn X
A4: 1 | B4: =SUM(Data!F2:F9)*100 -> 94.485804 | D4: =Data!F10 -> 2.3434343 | E4: =Data!G10 -> 2.4242424 | F4: =Data!H10 -> 2.5050505 | G4: =Data!I10 -> 2.5858586 | H4: =Data!J10 -> 2.6666667 | I4: =Data!K10 -> 2.7474747 | J4: =Data!L10 -> 2.8282828 | K4: =Data!M10 -> 2.9090909 | L4: =Data!N10 -> 2.989899 | N4: =SUM(Data!N2:N9)*100 -> 98.025069 | O4: 1
A5: 2 | B5: =SUM(Data!F12:F20)*100 -> 99.999421 | D5: =Data!F21 -> 2.6363116 | E5: =Data!G21 -> 2.7271983 | F5: =Data!H21 -> 2.818077 | G5: =Data!I21 -> 2.9089451 | H5: =Data!J21 -> 2.9997995 | I5: =Data!K21 -> 3.0906364 | J5: =Data!L21 -> 3.1814511 | K5: =Data!M21 -> 3.2722378 | L5: =Data!N21 -> 3.3629896 | N5: 100 | O5: 2
A6: 3 | B6: =B5 -> 99.999421 | D6: =Data!F32 -> 2.9288751 | E6: =Data!G32 -> 3.0297135 | F6: =Data!H32 -> 3.1304927 | G6: =Data!I32 -> 3.2311962 | H6: =Data!J32 -> 3.3318035 | I6: =Data!K32 -> 3.4322897 | J6: =Data!L32 -> 3.5326252 | K6: =Data!M32 -> 3.6327742 | L6: =Data!N32 -> 3.7326944 | N6: =N5 -> 100 | O6: 3
A7: 4 | B7: =B6 -> 99.999421 | D7: =Data!F43 -> 3.2203811 | E7: =Data!G43 -> 3.3307676 | F7: =Data!H43 -> 3.4409188 | G7: =Data!I43 -> 3.5507735 | H7: =Data!J43 -> 3.6602585 | I7: =Data!K43 -> 3.769287 | J7: =Data!L43 -> 3.877757 | K7: =Data!M43 -> 3.9855494 | L7: =Data!N43 -> 4.0925265 | N7: =N6 -> 100 | O7: 4
A8: 5 | B8: =B7 -> 99.999421 | D8: =Data!F54 -> 3.509261 | E8: =Data!G54 -> 3.6282567 | F8: =Data!H54 -> 3.7465754 | G8: =Data!I54 -> 3.8640565 | H8: =Data!J54 -> 3.9805125 | I8: =Data!K54 -> 4.0957264 | J8: =Data!L54 -> 4.2094496 | K8: =Data!M54 -> 4.3213997 | L8: =Data!N54 -> 4.4312588 | N8: =N7 -> 100 | O8: 5
A11: Turn | C11: Deck types | D11: Card draw | M11: Deck types | O11: Turn | P11: Notes
C12: Commander with draw | D12: 7 | E12: 8 | F12: 9 | G12: 10 | H12: 11 | I12: 12 | J12: 13 | K12: 14 | L12: 15 | M12: Combo | P12: Burst draw (Treasure Cruise) Card advantage (Phyrexian Arena)
B13: At least 1 by turn X | C13: Aggro | D13: Average number drawn | M13: Control | N13: At least 1 by turn X
A14: 1 | B14: =SUM(Data!P2:P9)*100 -> 45.630597 | D14: =Data!P10 -> 0.56565657 | E14: =Data!Q10 -> 0.64646465 | F14: =Data!R10 -> 0.72727273 | G14: =Data!S10 -> 0.80808081 | H14: =Data!T10 -> 0.88888889 | I14: =Data!U10 -> 0.96969697 | J14: =Data!V10 -> 1.0505051 | K14: =Data!W10 -> 1.1313131 | L14: =Data!X10 -> 1.2121212 | N14: =SUM(Data!X2:X9)*100 -> 74.535674 | O14: 1
A15: 2 | B15: =SUM(Data!P13:P20)*100 -> 49.812859 | D15: =Data!P21 -> 0.63636364 | E15: =Data!Q21 -> 0.72727273 | F15: =Data!R21 -> 0.81818182 | G15: =Data!S21 -> 0.90909091 | H15: =Data!T21 -> 1 | I15: =Data!U21 -> 1.0909091 | J15: =Data!V21 -> 1.1818182 | K15: =Data!W21 -> 1.2727273 | L15: =Data!X21 -> 1.3636363 | N15: =SUM(Data!X13:X20)*100 -> 78.73309 | O15: 2
A16: 3 | B16: =SUM(Data!P24:P31)*100 -> 53.716303 | D16: =Data!P32 -> 0.70707071 | E16: =Data!Q32 -> 0.80808081 | F16: =Data!R32 -> 0.90909091 | G16: =Data!S32 -> 1.010101 | H16: =Data!T32 -> 1.1111111 | I16: =Data!U32 -> 1.2121212 | J16: =Data!V32 -> 1.3131313 | K16: =Data!W32 -> 1.4141413 | L16: =Data!X32 -> 1.5151513 | N16: =SUM(Data!X24:X31)*100 -> 82.277573 | O16: 3
A17: 4 | B17: =SUM(Data!P35:P42)*100 -> 57.356594 | D17: =Data!P43 -> 0.77777778 | E17: =Data!Q43 -> 0.88888889 | F17: =Data!R43 -> 1 | G17: =Data!S43 -> 1.1111111 | H17: =Data!T43 -> 1.2222222 | I17: =Data!U43 -> 1.3333333 | J17: =Data!V43 -> 1.4444443 | K17: =Data!W43 -> 1.555555 | L17: =Data!X43 -> 1.6666654 | N17: =SUM(Data!X35:X42)*100 -> 85.264487 | O17: 4
A18: 5 | B18: =SUM(Data!P46:P53)*100 -> 60.748683 | D18: =Data!P54 -> 0.84848485 | E18: =Data!Q54 -> 0.96969697 | F18: =Data!R54 -> 1.0909091 | G18: =Data!S54 -> 1.2121212 | H18: =Data!T54 -> 1.3333333 | I18: =Data!U54 -> 1.4545452 | J18: =Data!V54 -> 1.5757569 | K18: =Data!W54 -> 1.6969677 | L18: =Data!X54 -> 1.8181771 | N18: =SUM(Data!X46:X53)*100 -> 87.776181 | O18: 5
A21: Turn | C21: Deck types | D21: Single target removal | M21: Deck types | O21: Turn | P21: Notes
C22: Commander with removal | D22: 7 | E22: 8 | F22: 9 | G22: 10 | H22: 11 | I22: 12 | J22: 13 | K22: 14 | L22: 15 | M22: Weak to one card type | P22: 1:1 (Path to Exile) 2:1 or 3:1 (Soul Shatter) Counterspells (also 1:1)
B23: At least 1 by turn X | C23: Combo | D23: Average number drawn | M23: Control | N23: At least 1 by turn X
A24: 1 | B24: =SUM(Data!Z2:Z9)*100 -> 45.630597 | D24: =Data!Z10 -> 0.56565657 | E24: =Data!AA10 -> 0.64646465 | F24: =Data!AB10 -> 0.72727273 | G24: =Data!AC10 -> 0.80808081 | H24: =Data!AD10 -> 0.88888889 | I24: =Data!AE10 -> 0.96969697 | J24: =Data!AF10 -> 1.0505051 | K24: =Data!AG10 -> 1.1313131 | L24: =Data!AH10 -> 1.2121212 | N24: =SUM(Data!AH2:AH9)*100 -> 74.535674 | O24: 1
A25: 2 | B25: =SUM(Data!Z13:Z20)*100 -> 49.812859 | D25: =Data!Z21 -> 0.63636364 | E25: =Data!AA21 -> 0.72727273 | F25: =Data!AB21 -> 0.81818182 | G25: =Data!AC21 -> 0.90909091 | H25: =Data!AD21 -> 1 | I25: =Data!AE21 -> 1.0909091 | J25: =Data!AF21 -> 1.1818182 | K25: =Data!AG21 -> 1.2727273 | L25: =Data!AH21 -> 1.3636363 | N25: =SUM(Data!AH13:AH20)*100 -> 78.73309 | O25: 2
A26: 3 | B26: =SUM(Data!Z24:Z31)*100 -> 53.716303 | D26: =Data!Z32 -> 0.70707071 | E26: =Data!AA32 -> 0.80808081 | F26: =Data!AB32 -> 0.90909091 | G26: =Data!AC32 -> 1.010101 | H26: =Data!AD32 -> 1.1111111 | I26: =Data!AE32 -> 1.2121212 | J26: =Data!AF32 -> 1.3131313 | K26: =Data!AG32 -> 1.4141413 | L26: =Data!AH32 -> 1.5151513 | N26: =SUM(Data!AH24:AH31)*100 -> 82.277573 | O26: 3
A27: 4 | B27: =SUM(Data!Z35:Z42)*100 -> 57.356594 | D27: =Data!Z43 -> 0.77777778 | E27: =Data!AA43 -> 0.88888889 | F27: =Data!AB43 -> 1 | G27: =Data!AC43 -> 1.1111111 | H27: =Data!AD43 -> 1.2222222 | I27: =Data!AE43 -> 1.3333333 | J27: =Data!AF43 -> 1.4444443 | K27: =Data!AG43 -> 1.555555 | L27: =Data!AH43 -> 1.6666654 | N27: =SUM(Data!AH35:AH42)*100 -> 85.264487 | O27: 4
A28: 5 | B28: =SUM(Data!Z46:Z53)*100 -> 60.748683 | D28: =Data!Z54 -> 0.84848485 | E28: =Data!AA54 -> 0.96969697 | F28: =Data!AB54 -> 1.0909091 | G28: =Data!AC54 -> 1.2121212 | H28: =Data!AD54 -> 1.3333333 | I28: =Data!AE54 -> 1.4545452 | J28: =Data!AF54 -> 1.5757569 | K28: =Data!AG54 -> 1.6969677 | L28: =Data!AH54 -> 1.8181771 | N28: =SUM(Data!AH46:AH53)*100 -> 87.776181 | O28: 5
A31: Turn | C31: Deck types | D31: Board wipes | M31: Deck types | O31: Turn | P31: Notes
C32: Creature deck | D32: 0 | E32: 1 | F32: 2 | G32: 3 | H32: 4 | I32: 5 | J32: 6 | K32: 7 | L32: 8 | M32: Control | P32: Bane of Progress is a board wipe too e.g. no artifacts in your deck = artifact wipe
B33: At least 1 by turn X | C33: Aggro | D33: Average number drawn | N33: At least 1 by turn X
A34: 1 | B34: =SUM(Data!AJ2:AJ9)*100 -> 0 | D34: =Data!AJ10 -> 0 | E34: =Data!AK10 -> 0.080808081 | F34: =Data!AL10 -> 0.16161616 | G34: =Data!AM10 -> 0.24242424 | H34: =Data!AN10 -> 0.32323232 | I34: =Data!AO10 -> 0.4040404 | J34: =Data!AP10 -> 0.48484848 | K34: =Data!AQ10 -> 0.56565657 | L34: =Data!AR10 -> 0.64646465 | N34: =SUM(Data!AR2:AR9)*100 -> 50.358371 | O34: 1
A35: 2 | B35: =SUM(Data!AJ13:AJ20)*100 -> 0 | D35: =Data!AJ21 -> 0 | E35: =Data!AK21 -> 0.090909091 | F35: =Data!AL21 -> 0.18181818 | G35: =Data!AM21 -> 0.27272727 | H35: =Data!AN21 -> 0.36363636 | I35: =Data!AO21 -> 0.45454545 | J35: =Data!AP21 -> 0.54545455 | K35: =Data!AQ21 -> 0.63636364 | L35: =Data!AR21 -> 0.72727273 | N35: =SUM(Data!AR13:AR20)*100 -> 54.72247 | O35: 2
A36: 3 | B36: =SUM(Data!AJ24:AJ31)*100 -> 0 | D36: =Data!AJ232 -> 0 | E36: =Data!AK232 -> 0 | F36: =Data!AL232 -> 0 | G36: =Data!AM232 -> 0 | H36: =Data!AN232 -> 0 | I36: =Data!AO232 -> 0 | J36: =Data!AP232 -> 0 | K36: =Data!AQ232 -> 0 | L36: =Data!AR232 -> 0 | N36: =SUM(Data!AR24:AR31)*100 -> 58.74714 | O36: 3
A37: 4 | B37: =SUM(Data!AJ35:AJ42)*100 -> 0 | D37: =Data!AJ43 -> 0 | E37: =Data!AK43 -> 0.11111111 | F37: =Data!AL43 -> 0.22222222 | G37: =Data!AM43 -> 0.33333333 | H37: =Data!AN43 -> 0.44444444 | I37: =Data!AO43 -> 0.55555556 | J37: =Data!AP43 -> 0.66666667 | K37: =Data!AQ43 -> 0.77777778 | L37: =Data!AR43 -> 0.88888889 | N37: =SUM(Data!AR35:AR42)*100 -> 62.455262 | O37: 4
A38: 5 | B38: =SUM(Data!AJ46:AJ53)*100 -> 0 | D38: =Data!AJ54 -> 0 | E38: =Data!AK54 -> 0.12121212 | F38: =Data!AL54 -> 0.24242424 | G38: =Data!AM54 -> 0.36363636 | H38: =Data!AN54 -> 0.48484848 | I38: =Data!AO54 -> 0.60606061 | J38: =Data!AP54 -> 0.72727273 | K38: =Data!AQ54 -> 0.84848485 | L38: =Data!AR54 -> 0.96969697 | N38: =SUM(Data!AR46:AR53)*100 -> 65.86842 | O38: 5
A41: Turn | C41: Deck types | D41: Ramp | M41: Deck types | O41: Turn | P41: Notes
C42: Low curve | D42: 9 | E42: 10 | F42: 11 | G42: 12 | H42: 13 | I42: 14 | J42: 15 | K42: 16 | L42: 17 | M42: Landfall | P42: PERMANENT source of mana Dark Ritual, Jeweled Lotus are not ramp Extra land drops (Exploration, Burgeoning) Mana rocks (Sol Ring) Mana dorks (Birds of Paradise)
B43: At least 1 by turn X | C43: Aggro | D43: Average number drawn | M43: High curve | N43: At least 1 by turn X
A44: 1 | B44: =SUM(Data!AT2:AT9)*100 -> 54.72247 | D44: =Data!AT10 -> 0.72727273 | E44: =Data!AU10 -> 0.80808081 | F44: =Data!AV10 -> 0.88888889 | G44: =Data!AW10 -> 0.96969697 | H44: =Data!AX10 -> 1.0505051 | I44: =Data!AY10 -> 1.1313131 | J44: =Data!AZ10 -> 1.2121212 | K44: =Data!BA10 -> 1.2929293 | L44: =Data!BB10 -> 1.3737374 | N44: =SUM(Data!BB2:BB9)*100 -> 79.181489 | O44: 1
A45: 2 | B45: =SUM(Data!AT13:AT20)*100 -> 59.200468 | D45: =Data!AT21 -> 0.81818182 | E45: =Data!AU21 -> 0.90909091 | F45: =Data!AV21 -> 1 | G45: =Data!AW21 -> 1.0909091 | H45: =Data!AX21 -> 1.1818182 | I45: =Data!AY21 -> 1.2727273 | J45: =Data!AZ21 -> 1.3636363 | K45: =Data!BA21 -> 1.4545454 | L45: =Data!BB21 -> 1.5454544 | N45: =SUM(Data!BB13:BB20)*100 -> 83.07066 | O45: 2
A46: 3 | B46: =SUM(Data!AT24:AT31)*100 -> 63.280421 | D46: =Data!AT32 -> 0.90909091 | E46: =Data!AU32 -> 1.010101 | F46: =Data!AV32 -> 1.1111111 | G46: =Data!AW32 -> 1.2121212 | H46: =Data!AX32 -> 1.3131313 | I46: =Data!AY32 -> 1.4141413 | J46: =Data!AZ32 -> 1.5151513 | K46: =Data!BA32 -> 1.6161611 | L46: =Data!BB32 -> 1.7171706 | N46: =SUM(Data!BB24:BB31)*100 -> 86.268413 | O46: 3
A47: 4 | B47: =SUM(Data!AT35:AT42)*100 -> 66.993637 | D47: =Data!AT43 -> 1 | E47: =Data!AU43 -> 1.1111111 | F47: =Data!AV43 -> 1.2222222 | G47: =Data!AW43 -> 1.3333333 | H47: =Data!AX43 -> 1.4444443 | I47: =Data!AY43 -> 1.555555 | J47: =Data!AZ43 -> 1.6666654 | K47: =Data!BA43 -> 1.7777749 | L47: =Data!BB43 -> 1.888883 | N47: =SUM(Data!BB35:BB42)*100 -> 88.891245 | O47: 4
A48: 5 | B48: =SUM(Data!AT46:AT53)*100 -> 70.369288 | D48: =Data!AT54 -> 1.0909091 | E48: =Data!AU54 -> 1.2121212 | F48: =Data!AV54 -> 1.3333333 | G48: =Data!AW54 -> 1.4545452 | H48: =Data!AX54 -> 1.5757569 | I48: =Data!AY54 -> 1.6969677 | J48: =Data!AZ54 -> 1.8181771 | K48: =Data!BA54 -> 1.9393834 | L48: =Data!BB54 -> 2.0605844 | N48: =SUM(Data!BB46:BB53)*100 -> 91.037067 | O48: 5
...

Sheet Land Types
A1: Land type | B1: Price | C1: Tapped? | D1: Basic type? | E1: Note
A2: Pain | B2: Low | C2: No | D2: No | E2: Good budget option, self damage
A3: Shock | B3: High | C3: No | D3: Yes | E3: Better pain lands, expensive, basic types, best lands
A4: Fetch | B4: Very high | C4: No | D4: No | E4: Best lands, very expensive
A5: Filter | B5: Very low - low | C5: No | D5: No | E5: Two kinds: - any mana to two colors (e.g. Skycloud Expanse) - colored to two colors (e.g. Fetid Heath) Good budget option, a bit clunky
A6: Scry (Temples) | B6: Very low | C6: Yes | D6: No | E6: Best slow lands
A7: Battle | B7: Low | C7: Maybe | D7: Yes | E7: Basic types (Skyshroud Claim)
A8: Check | B8: Medium | C8: Maybe | D8: No | E8: Very good in 2 or 3 colors
A9: Bicycle | B9: Medium | C9: Yes | D9: No | E9: Two colors, cycling for 2 colorless Slow, but easy to cycle in the late game
A10: Bond | B10: Medium - high | C10: Maybe | D10: No | E10: Checks for two opponents. In Commander almost as good as a shock land, great
A11: Pathway | B11: Low - high | C11: No | D11: No | E11: Very good especially in fewer colors
A12: Slow | B12: Medium - high | C12: Maybe | D12: No | E12: Untapped from your third land on. Great for colors you only need later
A13: Tricycle | B13: Medium - very high | C13: Yes | D13: Yes | E13: Basic types, cycling 3, enters tapped but very good in 4 to 5 colors

Sheet Mana Curve
A1: Analysis of cEDH decks:
A2: Mana value | B2: Number of cards | C2: Note
A3: 0 | B3: 1.9 | C3: Mostly ramp or one-mana removal
A4: 1 | B4: 12.9
A5: 2 | B5: 16.2 | C5: Ramp, creatures, key spells
A6: 3 | B6: 16.7 | C6: From here, casting two spells a turn gets hard
A7: 4 | B7: 9.5 | C7: Strong effects, two spells a turn very unlikely These cards must be WORTH a whole turn
A8: 5 | B8: 4.4 | C8: See mana value 4. Fewer expensive cards mean fewer mulligans + cards you cannot cast do nothing
A9: 6 | B9: 3.2 | C9: See above. Hands with too many expensive cards are a big drawback from here and mana value 5 on: win con territory. A strong effect that wins
A10: 7+ | B10: 1.9 | C10: Expropriate etc. win cons, ETBs that turn the game around
A13: Notes:
A14: Lower the mana curve where possible: more cards played = more effects = higher win rate, e.g. Nature's Claim vs. Krosan Grip Cards like Dig Through Time rarely cost their printed mana value = count them in a lower slot Decks with big effects are more expensive than those without. Only a guide, not a rule. Make sure the deck does not get too top-heavy Casual groups: MUCH more casual than cEDH, the mana curve does not need to be hyper-optimized. More flavor, less 5-color goodstuff

Sheet Deck 1 - Superfriends
A1: Card role | B1: Count | C1: Reason | D1: Note
A2: Land | B2: 34 | C2: Fairly standard | D2: 31 lands + 3 MDFCs
A3: Draw | B3: 10 | C3: Find the win con; planeswalkers are gone without a board wipe | D3: Could be fewer, Prismatic Bridge "draws" cards
A4: Single target removal | B4: 10 | C4: Trample and flying are a problem, mostly creature removal
A5: Board wipes | B5: 10 | C5: Planeswalkers survive wipes, so they are one-sided wipes | D5: Maybe 1 or 2 more
A6: Ramp | B6: 12 | C6: Mostly color fixing, almost only enchantments, hardly any artifacts or creatures
A8: Win cons | C8: Doubling Season + Dreadhorde General | D8: More win cons because every piece also works on its own Commander + ONE more card is a very good win con
C9: Doubling Season + Nicol Bolas, Dragon-God
C10: Doubling Season + Nicol Bolas, God-Pharaoh
C11: Doubling Season + Chandra, Torch of Defiance
C12: Jokulhaups + Prismatic Bridge
C13: Obliterate + Prismatic Bridge
A15: Rest | C15: Supports the game plan, prevents attacks or speeds up ultimates | D15: Evolution Sage, Sublime Artificier, Dueling Grounds Pramikon, Sphere of Safety, Blind Obedience

Sheet Data
A1: 0 | B1: =_xlfn.HYPGEOM.DIST(A1,'Hypergeometric Calculator'!C$3,'Hypergeometric Calculator'!C$4,'Hypergeometric Calculator'!C$2,FALSE) -> 0.22728232 | C1: 8 | F1: =_xlfn.HYPGEOM.DIST($A1,$C$1,'Benchmarks by Card Role'!D$2,99,FALSE) -> 0.055141959 | G1: =_xlfn.HYPGEOM.DIST($A1,$C$1,'Benchmarks by Card Role'!E$2,99,FALSE) -> 0.048840021 | H1: =_xlfn.HYPGEOM.DIST($A1,$C$1,'Benchmarks by Card Role'!F$2,99,FALSE) -> 0.04317741 | I1: =_xlfn.HYPGEOM.DIST($A1,$C$1,'Benchmarks by Card Role'!G$2,99,FALSE) -> 0.038097714 | J1: =_xlfn.HYPGEOM.DIST($A1,$C$1,'Benchmarks by Card Role'!H$2,99,FALSE) -> 0.033548734 | K1: =_xlfn.HYPGEOM.DIST($A1,$C$1,'Benchmarks by Card Role'!I$2,99,FALSE) -> 0.02948222 | L1: =_xlfn.HYPGEOM.DIST($A1,$C$1,'Benchmarks by Card Role'!J$2,99,FALSE) -> 0.025853639 | M1: =_xlfn.HYPGEOM.DIST($A1,$C$1,'Benchmarks by Card Role'!K$2,99,FALSE) -> 0.022621934 | N1: =_xlfn.HYPGEOM.DIST($A1,$C$1,'Benchmarks by Card Role'!L$2,99,FALSE) -> 0.019749308 | P1: =_xlfn.HYPGEOM.DIST($A1,$C$1,'Benchmarks by Card Role'!D$12,99,FALSE) -> 0.54369403 | Q1: =_xlfn.HYPGEOM.DIST($A1,$C$1,'Benchmarks by Card Role'!E$12,99,FALSE) -> 0.49641629 | R1: =_xlfn.HYPGEOM.DIST($A1,$C$1,'Benchmarks by Card Role'!F$12,99,FALSE) -> 0.4527753 | S1: =_xlfn.HYPGEOM.DIST($A1,$C$1,'Benchmarks by Card Role'!G$12,99,FALSE) -> 0.4125286 | T1: =_xlfn.HYPGEOM.DIST($A1,$C$1,'Benchmarks by Card Role'!H$12,99,FALSE) -> 0.37544738 | U1: =_xlfn.HYPGEOM.DIST($A1,$C$1,'Benchmarks by Card Role'!I$12,99,FALSE) -> 0.3413158 | V1: =_xlfn.HYPGEOM.DIST($A1,$C$1,'Benchmarks by Card Role'!J$12,99,FALSE) -> 0.30993044 | W1: =_xlfn.HYPGEOM.DIST($A1,$C$1,'Benchmarks by Card Role'!K$12,99,FALSE) -> 0.2810997 | X1: =_xlfn.HYPGEOM.DIST($A1,$C$1,'Benchmarks by Card Role'!L$12,99,FALSE) -> 0.25464326 | Z1: =_xlfn.HYPGEOM.DIST($A1,$C$1,'Benchmarks by Card Role'!D$22,99,FALSE) -> 0.54369403 | AA1: =_xlfn.HYPGEOM.DIST($A1,$C$1,'Benchmarks by Card Role'!E$22,99,FALSE) -> 0.49641629 | AB1: =_xlfn.HYPGEOM.DIST($A1,$C$1,'Benchmarks by Card Role'!F$22,99,FALSE) -> 0.4527753 | AC1: =_xlfn.HYPGEOM.DIST($A1,$C$1,'Benchmarks by Card Role'!G$22,99,FALSE) -> 0.4125286 | AD1: =_xlfn.HYPGEOM.DIST($A1,$C$1,'Benchmarks by Card Role'!H$22,99,FALSE) -> 0.37544738 | AE1: =_xlfn.HYPGEOM.DIST($A1,$C$1,'Benchmarks by Card Role'!I$22,99,FALSE) -> 0.3413158 | AF1: =_xlfn.HYPGEOM.DIST($A1,$C$1,'Benchmarks by Card Role'!J$22,99,FALSE) -> 0.30993044 | AG1: =_xlfn.HYPGEOM.DIST($A1,$C$1,'Benchmarks by Card Role'!K$22,99,FALSE) -> 0.2810997 | AH1: =_xlfn.HYPGEOM.DIST($A1,$C$1,'Benchmarks by Card Role'!L$22,99,FALSE) -> 0.25464326 | AJ1: =_xlfn.HYPGEOM.DIST($A1,$C$1,'Benchmarks by Card Role'!D$32,99,FALSE) -> 1 | AK1: =_xlfn.HYPGEOM.DIST($A1,$C$1,'Benchmarks by Card Role'!E$32,99,FALSE) -> 0.91919192 | AL1: =_xlfn.HYPGEOM.DIST($A1,$C$1,'Benchmarks by Card Role'!F$32,99,FALSE) -> 0.84415584 | AM1: =_xlfn.HYPGEOM.DIST($A1,$C$1,'Benchmarks by Card Role'!G$32,99,FALSE) -> 0.77453474 | AN1: =_xlfn.HYPGEOM.DIST($A1,$C$1,'Benchmarks by Card Role'!H$32,99,FALSE) -> 0.70999018 | AO1: =_xlfn.HYPGEOM.DIST($A1,$C$1,'Benchmarks by Card Role'!I$32,99,FALSE) -> 0.65020153 | AP1: =_xlfn.HYPGEOM.DIST($A1,$C$1,'Benchmarks by Card Role'!J$32,99,FALSE) -> 0.59486523 | AQ1: =_xlfn.HYPGEOM.DIST($A1,$C$1,'Benchmarks by Card Role'!K$32,99,FALSE) -> 0.54369403 | AR1: =_xlfn.HYPGEOM.DIST($A1,$C$1,'Benchmarks by Card Role'!L$32,99,FALSE) -> 0.49641629 | AT1: =_xlfn.HYPGEOM.DIST($A1,$C$1,'Benchmarks by Card Role'!D$42,99,FALSE) -> 0.4527753 | AU1: =_xlfn.HYPGEOM.DIST($A1,$C$1,'Benchmarks by Card Role'!E$42,99,FALSE) -> 0.4125286 | AV1: =_xlfn.HYPGEOM.DIST($A1,$C$1,'Benchmarks by Card Role'!F$42,99,FALSE) -> 0.37544738 | AW1: =_xlfn.HYPGEOM.DIST($A1,$C$1,'Benchmarks by Card Role'!G$42,99,FALSE) -> 0.3413158 | AX1: =_xlfn.HYPGEOM.DIST($A1,$C$1,'Benchmarks by Card Role'!H$42,99,FALSE) -> 0.30993044 | AY1: =_xlfn.HYPGEOM.DIST($A1,$C$1,'Benchmarks by Card Role'!I$42,99,FALSE) -> 0.2810997 | AZ1: =_xlfn.HYPGEOM.DIST($A1,$C$1,'Benchmarks by Card Role'!J$42,99,FALSE) -> 0.25464326 | BA1: =_xlfn.HYPGEOM.DIST($A1,$C$1,'Benchmarks by Card Role'!K$42,99,FALSE) -> 0.23039152 | BB1: =_xlfn.HYPGEOM.DIST($A1,$C$1,'Benchmarks by Card Role'!L$42,99,FALSE) -> 0.20818511
A2: 1 | B2: =_xlfn.HYPGEOM.DIST(A2,'Hypergeometric Calculator'!C$3,'Hypergeometric Calculator'!C$4,'Hypergeometric Calculator'!C$2,FALSE) -> 0.3837234 | C2: 9 | F2: =_xlfn.HYPGEOM.DIST($A2,$C$1,'Benchmarks by Card Role'!D$2,99,FALSE) -> 0.20306245 | G2: =_xlfn.HYPGEOM.DIST($A2,$C$1,'Benchmarks by Card Role'!E$2,99,FALSE) -> 0.18905814 | H2: =_xlfn.HYPGEOM.DIST($A2,$C$1,'Benchmarks by Card Role'!F$2,99,FALSE) -> 0.17554094 | I2: =_xlfn.HYPGEOM.DIST($A2,$C$1,'Benchmarks by Card Role'!G$2,99,FALSE) -> 0.16255025 | J2: =_xlfn.HYPGEOM.DIST($A2,$C$1,'Benchmarks by Card Role'!H$2,99,FALSE) -> 0.15011637 | K2: =_xlfn.HYPGEOM.DIST($A2,$C$1,'Benchmarks by Card Role'!I$2,99,FALSE) -> 0.13826145 | L2: =_xlfn.HYPGEOM.DIST($A2,$C$1,'Benchmarks by Card Role'!J$2,99,FALSE) -> 0.12700033 | M2: =_xlfn.HYPGEOM.DIST($A2,$C$1,'Benchmarks by Card Role'!K$2,99,FALSE) -> 0.11634138 | N2: =_xlfn.HYPGEOM.DIST($A2,$C$1,'Benchmarks by Card Role'!L$2,99,FALSE) -> 0.10628718 | P2: =_xlfn.HYPGEOM.DIST($A2,$C$1,'Benchmarks by Card Role'!D$12,99,FALSE) -> 0.35819842 | Q2: =_xlfn.HYPGEOM.DIST($A2,$C$1,'Benchmarks by Card Role'!E$12,99,FALSE) -> 0.37822193 | R2: =_xlfn.HYPGEOM.DIST($A2,$C$1,'Benchmarks by Card Role'!F$12,99,FALSE) -> 0.39276893 | S2: =_xlfn.HYPGEOM.DIST($A2,$C$1,'Benchmarks by Card Role'!G$12,99,FALSE) -> 0.40246693 | T2: =_xlfn.HYPGEOM.DIST($A2,$C$1,'Benchmarks by Card Role'!H$12,99,FALSE) -> 0.40789345 | U2: =_xlfn.HYPGEOM.DIST($A2,$C$1,'Benchmarks by Card Role'!I$12,99,FALSE) -> 0.40957896 | V2: =_xlfn.HYPGEOM.DIST($A2,$C$1,'Benchmarks by Card Role'!J$12,99,FALSE) -> 0.40800969 | W2: =_xlfn.HYPGEOM.DIST($A2,$C$1,'Benchmarks by Card Role'!K$12,99,FALSE) -> 0.40363034 | X2: =_xlfn.HYPGEOM.DIST($A2,$C$1,'Benchmarks by Card Role'!L$12,99,FALSE) -> 0.39684664 | Z2: =_xlfn.HYPGEOM.DIST($A2,$C$1,'Benchmarks by Card Role'!D$22,99,FALSE) -> 0.35819842 | AA2: =_xlfn.HYPGEOM.DIST($A2,$C$1,'Benchmarks by Card Role'!E$22,99,FALSE) -> 0.37822193 | AB2: =_xlfn.HYPGEOM.DIST($A2,$C$1,'Benchmarks by Card Role'!F$22,99,FALSE) -> 0.39276893 | AC2: =_xlfn.HYPGEOM.DIST($A2,$C$1,'Benchmarks by Card Role'!G$22,99,FALSE) -> 0.40246693 | AD2: =_xlfn.HYPGEOM.DIST($A2,$C$1,'Benchmarks by Card Role'!H$22,99,FALSE) -> 0.40789345 | AE2: =_xlfn.HYPGEOM.DIST($A2,$C$1,'Benchmarks by Card Role'!I$22,99,FALSE) -> 0.40957896 | AF2: =_xlfn.HYPGEOM.DIST($A2,$C$1,'Benchmarks by Card Role'!J$22,99,FALSE) -> 0.40800969 | AG2: =_xlfn.HYPGEOM.DIST($A2,$C$1,'Benchmarks by Card Role'!K$22,99,FALSE) -> 0.40363034 | AH2: =_xlfn.HYPGEOM.DIST($A2,$C$1,'Benchmarks by Card Role'!L$22,99,FALSE) -> 0.39684664 | AJ2: =_xlfn.HYPGEOM.DIST($A2,$C$1,'Benchmarks by Card Role'!D$32,99,FALSE) -> 0 | AK2: =_xlfn.HYPGEOM.DIST($A2,$C$1,'Benchmarks by Card Role'!E$32,99,FALSE) -> 0.080808081 | AL2: =_xlfn.HYPGEOM.DIST($A2,$C$1,'Benchmarks by Card Role'!F$32,99,FALSE) -> 0.15007215 | AM2: =_xlfn.HYPGEOM.DIST($A2,$C$1,'Benchmarks by Card Role'!G$32,99,FALSE) -> 0.2088633 | AN2: =_xlfn.HYPGEOM.DIST($A2,$C$1,'Benchmarks by Card Role'!H$32,99,FALSE) -> 0.25817825 | AO2: =_xlfn.HYPGEOM.DIST($A2,$C$1,'Benchmarks by Card Role'!I$32,99,FALSE) -> 0.29894323 | AP2: =_xlfn.HYPGEOM.DIST($A2,$C$1,'Benchmarks by Card Role'!J$32,99,FALSE) -> 0.3320178 | AQ2: =_xlfn.HYPGEOM.DIST($A2,$C$1,'Benchmarks by Card Role'!K$32,99,FALSE) -> 0.35819842 | AR2: =_xlfn.HYPGEOM.DIST($A2,$C$1,'Benchmarks by Card Role'!L$32,99,FALSE) -> 0.37822193 | AT2: =_xlfn.HYPGEOM.DIST($A2,$C$1,'Benchmarks by Card Role'!D$42,99,FALSE) -> 0.39276893 | AU2: =_xlfn.HYPGEOM.DIST($A2,$C$1,'Benchmarks by Card Role'!E$42,99,FALSE) -> 0.40246693 | AV2: =_xlfn.HYPGEOM.DIST($A2,$C$1,'Benchmarks by Card Role'!F$42,99,FALSE) -> 0.40789345 | AW2: =_xlfn.HYPGEOM.DIST($A2,$C$1,'Benchmarks by Card Role'!G$42,99,FALSE) -> 0.40957896 | AX2: =_xlfn.HYPGEOM.DIST($A2,$C$1,'Benchmarks by Card Role'!H$42,99,FALSE) -> 0.40800969 | AY2: =_xlfn.HYPGEOM.DIST($A2,$C$1,'Benchmarks by Card Role'!I$42,99,FALSE) -> 0.40363034 | AZ2: =_xlfn.HYPGEOM.DIST($A2,$C$1,'Benchmarks by Card Role'!J$42,99,FALSE) -> 0.39684664 | BA2: =_xlfn.HYPGEOM.DIST($A2,$C$1,'Benchmarks by Card Role'!K$42,99,FALSE) -> 0.38802782 | BB2: =_xlfn.HYPGEOM.DIST($A2,$C$1,'Benchmarks by Card Role'!L$42,99,FALSE) -> 0.377509
A3: 2 | B3: =_xlfn.HYPGEOM.DIST(A3,'Hypergeometric Calculator'!C$3,'Hypergeometric Calculator'!C$4,'Hypergeometric Calculator'!C$2,FALSE) -> 0.26565466 | C3: 10 | F3: =_xlfn.HYPGEOM.DIST($A3,$C$1,'Benchmarks by Card Role'!D$2,99,FALSE) -> 0.31093938 | G3: =_xlfn.HYPGEOM.DIST($A3,$C$1,'Benchmarks by Card Role'!E$2,99,FALSE) -> 0.30459368 | H3: =_xlfn.HYPGEOM.DIST($A3,$C$1,'Benchmarks by Card Role'!F$2,99,FALSE) -> 0.29728708 | I3: =_xlfn.HYPGEOM.DIST($A3,$C$1,'Benchmarks by Card Role'!G$2,99,FALSE) -> 0.28912626 | J3: =_xlfn.HYPGEOM.DIST($A3,$C$1,'Benchmarks by Card Role'!H$2,99,FALSE) -> 0.28021722 | K3: =_xlfn.HYPGEOM.DIST($A3,$C$1,'Benchmarks by Card Role'!I$2,99,FALSE) -> 0.27066436 | L3: =_xlfn.HYPGEOM.DIST($A3,$C$1,'Benchmarks by Card Role'!J$2,99,FALSE) -> 0.26056965 | M3: =_xlfn.HYPGEOM.DIST($A3,$C$1,'Benchmarks by Card Role'!K$2,99,FALSE) -> 0.25003191 | N3: =_xlfn.HYPGEOM.DIST($A3,$C$1,'Benchmarks by Card Role'!L$2,99,FALSE) -> 0.23914616 | P3: =_xlfn.HYPGEOM.DIST($A3,$C$1,'Benchmarks by Card Role'!D$12,99,FALSE) -> 0.087467056 | Q3: =_xlfn.HYPGEOM.DIST($A3,$C$1,'Benchmarks by Card Role'!E$12,99,FALSE) -> 0.10901691 | R3: =_xlfn.HYPGEOM.DIST($A3,$C$1,'Benchmarks by Card Role'!F$12,99,FALSE) -> 0.13092298 | S3: =_xlfn.HYPGEOM.DIST($A3,$C$1,'Benchmarks by Card Role'!G$12,99,FALSE) -> 0.15274347 | T3: =_xlfn.HYPGEOM.DIST($A3,$C$1,'Benchmarks by Card Role'!H$12,99,FALSE) -> 0.17410086 | U3: =_xlfn.HYPGEOM.DIST($A3,$C$1,'Benchmarks by Card Role'!I$12,99,FALSE) -> 0.19467642 | V3: =_xlfn.HYPGEOM.DIST($A3,$C$1,'Benchmarks by Card Role'!J$12,99,FALSE) -> 0.21420509 | W3: =_xlfn.HYPGEOM.DIST($A3,$C$1,'Benchmarks by Card Role'!K$12,99,FALSE) -> 0.23247064 | X3: =_xlfn.HYPGEOM.DIST($A3,$C$1,'Benchmarks by Card Role'!L$12,99,FALSE) -> 0.24930109 | Z3: =_xlfn.HYPGEOM.DIST($A3,$C$1,'Benchmarks by Card Role'!D$22,99,FALSE) -> 0.087467056 | AA3: =_xlfn.HYPGEOM.DIST($A3,$C$1,'Benchmarks by Card Role'!E$22,99,FALSE) -> 0.10901691 | AB3: =_xlfn.HYPGEOM.DIST($A3,$C$1,'Benchmarks by Card Role'!F$22,99,FALSE) -> 0.13092298 | AC3: =_xlfn.HYPGEOM.DIST($A3,$C$1,'Benchmarks by Card Role'!G$22,99,FALSE) -> 0.15274347 | AD3: =_xlfn.HYPGEOM.DIST($A3,$C$1,'Benchmarks by Card Role'!H$22,99,FALSE) -> 0.17410086 | AE3: =_xlfn.HYPGEOM.DIST($A3,$C$1,'Benchmarks by Card Role'!I$22,99,FALSE) -> 0.19467642 | AF3: =_xlfn.HYPGEOM.DIST($A3,$C$1,'Benchmarks by Card Role'!J$22,99,FALSE) -> 0.21420509 | AG3: =_xlfn.HYPGEOM.DIST($A3,$C$1,'Benchmarks by Card Role'!K$22,99,FALSE) -> 0.23247064 | AH3: =_xlfn.HYPGEOM.DIST($A3,$C$1,'Benchmarks by Card Role'!L$22,99,FALSE) -> 0.24930109 | AJ3: =_xlfn.HYPGEOM.DIST($A3,$C$1,'Benchmarks by Card Role'!D$32,99,FALSE) -> 0 | AK3: =_xlfn.HYPGEOM.DIST($A3,$C$1,'Benchmarks by Card Role'!E$32,99,FALSE) -> 0 | AL3: =_xlfn.HYPGEOM.DIST($A3,$C$1,'Benchmarks by Card Role'!F$32,99,FALSE) -> 0.0057720058 | AM3: =_xlfn.HYPGEOM.DIST($A3,$C$1,'Benchmarks by Card Role'!G$32,99,FALSE) -> 0.016244923 | AN3: =_xlfn.HYPGEOM.DIST($A3,$C$1,'Benchmarks by Card Role'!H$32,99,FALSE) -> 0.030459231 | AO3: =_xlfn.HYPGEOM.DIST($A3,$C$1,'Benchmarks by Card Role'!I$32,99,FALSE) -> 0.047559151 | AP3: =_xlfn.HYPGEOM.DIST($A3,$C$1,'Benchmarks by Card Role'!J$32,99,FALSE) -> 0.066785191 | AQ3: =_xlfn.HYPGEOM.DIST($A3,$C$1,'Benchmarks by Card Role'!K$32,99,FALSE) -> 0.087467056 | AR3: =_xlfn.HYPGEOM.DIST($A3,$C$1,'Benchmarks by Card Role'!L$32,99,FALSE) -> 0.10901691 | AT3: =_xlfn.HYPGEOM.DIST($A3,$C$1,'Benchmarks by Card Role'!D$42,99,FALSE) -> 0.13092298 | AU3: =_xlfn.HYPGEOM.DIST($A3,$C$1,'Benchmarks by Card Role'!E$42,99,FALSE) -> 0.15274347 | AV3: =_xlfn.HYPGEOM.DIST($A3,$C$1,'Benchmarks by Card Role'!F$42,99,FALSE) -> 0.17410086 | AW3: =_xlfn.HYPGEOM.DIST($A3,$C$1,'Benchmarks by Card Role'!G$42,99,FALSE) -> 0.19467642 | AX3: =_xlfn.HYPGEOM.DIST($A3,$C$1,'Benchmarks by Card Role'!H$42,99,FALSE) -> 0.21420509 | AY3: =_xlfn.HYPGEOM.DIST($A3,$C$1,'Benchmarks by Card Role'!I$42,99,FALSE) -> 0.23247064 | AZ3: =_xlfn.HYPGEOM.DIST($A3,$C$1,'Benchmarks by Card Role'!J$42,99,FALSE) -> 0.24930109 | BA3: =_xlfn.HYPGEOM.DIST($A3,$C$1,'Benchmarks by Card Role'!K$42,99,FALSE) -> 0.26456442 | BB3: =_xlfn.HYPGEOM.DIST($A3,$C$1,'Benchmarks by Card Role'!L$42,99,FALSE) -> 0.27816452
A4: 3 | B4: =_xlfn.HYPGEOM.DIST(A4,'Hypergeometric Calculator'!C$3,'Hypergeometric Calculator'!C$4,'Hypergeometric Calculator'!C$2,FALSE) -> 0.098639706 | C4: 11 | F4: =_xlfn.HYPGEOM.DIST($A4,$C$1,'Benchmarks by Card Role'!D$2,99,FALSE) -> 0.25831887 | G4: =_xlfn.HYPGEOM.DIST($A4,$C$1,'Benchmarks by Card Role'!E$2,99,FALSE) -> 0.26651947 | H4: =_xlfn.HYPGEOM.DIST($A4,$C$1,'Benchmarks by Card Role'!F$2,99,FALSE) -> 0.27369287 | I4: =_xlfn.HYPGEOM.DIST($A4,$C$1,'Benchmarks by Card Role'!G$2,99,FALSE) -> 0.27979961 | J4: =_xlfn.HYPGEOM.DIST($A4,$C$1,'Benchmarks by Card Role'!H$2,99,FALSE) -> 0.28481094 | K4: =_xlfn.HYPGEOM.DIST($A4,$C$1,'Benchmarks by Card Role'!I$2,99,FALSE) -> 0.28870865 | L4: =_xlfn.HYPGEOM.DIST($A4,$C$1,'Benchmarks by Card Role'!J$2,99,FALSE) -> 0.29148469 | M4: =_xlfn.HYPGEOM.DIST($A4,$C$1,'Benchmarks by Card Role'!K$2,99,FALSE) -> 0.29314086 | N4: =_xlfn.HYPGEOM.DIST($A4,$C$1,'Benchmarks by Card Role'!L$2,99,FALSE) -> 0.29368827 | P4: =_xlfn.HYPGEOM.DIST($A4,$C$1,'Benchmarks by Card Role'!D$12,99,FALSE) -> 0.010053685 | Q4: =_xlfn.HYPGEOM.DIST($A4,$C$1,'Benchmarks by Card Role'!E$12,99,FALSE) -> 0.015211662 | R4: =_xlfn.HYPGEOM.DIST($A4,$C$1,'Benchmarks by Card Role'!F$12,99,FALSE) -> 0.021563785 | S4: =_xlfn.HYPGEOM.DIST($A4,$C$1,'Benchmarks by Card Role'!G$12,99,FALSE) -> 0.029093995 | T4: =_xlfn.HYPGEOM.DIST($A4,$C$1,'Benchmarks by Card Role'!H$12,99,FALSE) -> 0.037756814 | U4: =_xlfn.HYPGEOM.DIST($A4,$C$1,'Benchmarks by Card Role'!I$12,99,FALSE) -> 0.047482054 | V4: =_xlfn.HYPGEOM.DIST($A4,$C$1,'Benchmarks by Card Role'!J$12,99,FALSE) -> 0.05817916 | W4: =_xlfn.HYPGEOM.DIST($A4,$C$1,'Benchmarks by Card Role'!K$12,99,FALSE) -> 0.069741192 | X4: =_xlfn.HYPGEOM.DIST($A4,$C$1,'Benchmarks by Card Role'!L$12,99,FALSE) -> 0.082048461 | Z4: =_xlfn.HYPGEOM.DIST($A4,$C$1,'Benchmarks by Card Role'!D$22,99,FALSE) -> 0.010053685 | AA4: =_xlfn.HYPGEOM.DIST($A4,$C$1,'Benchmarks by Card Role'!E$22,99,FALSE) -> 0.015211662 | AB4: =_xlfn.HYPGEOM.DIST($A4,$C$1,'Benchmarks by Card Role'!F$22,99,FALSE) -> 0.021563785 | AC4: =_xlfn.HYPGEOM.DIST($A4,$C$1,'Benchmarks by Card Role'!G$22,99,FALSE) -> 0.029093995 | AD4: =_xlfn.HYPGEOM.DIST($A4,$C$1,'Benchmarks by Card Role'!H$22,99,FALSE) -> 0.037756814 | AE4: =_xlfn.HYPGEOM.DIST($A4,$C$1,'Benchmarks by Card Role'!I$22,99,FALSE) -> 0.047482054 | AF4: =_xlfn.HYPGEOM.DIST($A4,$C$1,'Benchmarks by Card Role'!J$22,99,FALSE) -> 0.05817916 | AG4: =_xlfn.HYPGEOM.DIST($A4,$C$1,'Benchmarks by Card Role'!K$22,99,FALSE) -> 0.069741192 | AH4: =_xlfn.HYPGEOM.DIST($A4,$C$1,'Benchmarks by Card Role'!L$22,99,FALSE) -> 0.082048461 | AJ4: =_xlfn.HYPGEOM.DIST($A4,$C$1,'Benchmarks by Card Role'!D$32,99,FALSE) -> 0 | AK4: =_xlfn.HYPGEOM.DIST($A4,$C$1,'Benchmarks by Card Role'!E$32,99,FALSE) -> 0 | AL4: =_xlfn.HYPGEOM.DIST($A4,$C$1,'Benchmarks by Card Role'!F$32,99,FALSE) -> 0 | AM4: =_xlfn.HYPGEOM.DIST($A4,$C$1,'Benchmarks by Card Role'!G$32,99,FALSE) -> 0.00035703128 | AN4: =_xlfn.HYPGEOM.DIST($A4,$C$1,'Benchmarks by Card Role'!H$32,99,FALSE) -> 0.0013537436 | AO4: =_xlfn.HYPGEOM.DIST($A4,$C$1,'Benchmarks by Card Role'!I$32,99,FALSE) -> 0.0032062349 | AP4: =_xlfn.HYPGEOM.DIST($A4,$C$1,'Benchmarks by Card Role'!J$32,99,FALSE) -> 0.006071381 | AQ4: =_xlfn.HYPGEOM.DIST($A4,$C$1,'Benchmarks by Card Role'!K$32,99,FALSE) -> 0.010053685 | AR4: =_xlfn.HYPGEOM.DIST($A4,$C$1,'Benchmarks by Card Role'!L$32,99,FALSE) -> 0.015211662 | AT4: =_xlfn.HYPGEOM.DIST($A4,$C$1,'Benchmarks by Card Role'!D$42,99,FALSE) -> 0.021563785 | AU4: =_xlfn.HYPGEOM.DIST($A4,$C$1,'Benchmarks by Card Role'!E$42,99,FALSE) -> 0.029093995 | AV4: =_xlfn.HYPGEOM.DIST($A4,$C$1,'Benchmarks by Card Role'!F$42,99,FALSE) -> 0.037756814 | AW4: =_xlfn.HYPGEOM.DIST($A4,$C$1,'Benchmarks by Card Role'!G$42,99,FALSE) -> 0.047482054 | AX4: =_xlfn.HYPGEOM.DIST($A4,$C$1,'Benchmarks by Card Role'!H$42,99,FALSE) -> 0.05817916 | AY4: =_xlfn.HYPGEOM.DIST($A4,$C$1,'Benchmarks by Card Role'!I$42,99,FALSE) -> 0.069741192 | AZ4: =_xlfn.HYPGEOM.DIST($A4,$C$1,'Benchmarks by Card Role'!J$42,99,FALSE) -> 0.082048461 | BA4: =_xlfn.HYPGEOM.DIST($A4,$C$1,'Benchmarks by Card Role'!K$42,99,FALSE) -> 0.094971845 | BB4: =_xlfn.HYPGEOM.DIST($A4,$C$1,'Benchmarks by Card Role'!L$42,99,FALSE) -> 0.10837579
A5: 4 | B5: =_xlfn.HYPGEOM.DIST(A5,'Hypergeometric Calculator'!C$3,'Hypergeometric Calculator'!C$4,'Hypergeometric Calculator'!C$2,FALSE) -> 0.021577436 | C5: 12 | F5: =_xlfn.HYPGEOM.DIST($A5,$C$1,'Benchmarks by Card Role'!D$2,99,FALSE) -> 0.12720247 | G5: =_xlfn.HYPGEOM.DIST($A5,$C$1,'Benchmarks by Card Role'!E$2,99,FALSE) -> 0.13838511 | H5: =_xlfn.HYPGEOM.DIST($A5,$C$1,'Benchmarks by Card Role'!F$2,99,FALSE) -> 0.14967579 | I5: =_xlfn.HYPGEOM.DIST($A5,$C$1,'Benchmarks by Card Role'!G$2,99,FALSE) -> 0.16099581 | J5: =_xlfn.HYPGEOM.DIST($A5,$C$1,'Benchmarks by Card Role'!H$2,99,FALSE) -> 0.17226468 | K5: =_xlfn.HYPGEOM.DIST($A5,$C$1,'Benchmarks by Card Role'!I$2,99,FALSE) -> 0.18340099 | L5: =_xlfn.HYPGEOM.DIST($A5,$C$1,'Benchmarks by Card Role'!J$2,99,FALSE) -> 0.19432313 | M5: =_xlfn.HYPGEOM.DIST($A5,$C$1,'Benchmarks by Card Role'!K$2,99,FALSE) -> 0.20495018 | N5: =_xlfn.HYPGEOM.DIST($A5,$C$1,'Benchmarks by Card Role'!L$2,99,FALSE) -> 0.21520261 | P5: =_xlfn.HYPGEOM.DIST($A5,$C$1,'Benchmarks by Card Role'!D$12,99,FALSE) -> 0.00057123208 | Q5: =_xlfn.HYPGEOM.DIST($A5,$C$1,'Benchmarks by Card Role'!E$12,99,FALSE) -> 0.0010927918 | R5: =_xlfn.HYPGEOM.DIST($A5,$C$1,'Benchmarks by Card Role'!F$12,99,FALSE) -> 0.0018805626 | S5: =_xlfn.HYPGEOM.DIST($A5,$C$1,'Benchmarks by Card Role'!G$12,99,FALSE) -> 0.0029949701 | T5: =_xlfn.HYPGEOM.DIST($A5,$C$1,'Benchmarks by Card Role'!H$12,99,FALSE) -> 0.0044948588 | U5: =_xlfn.HYPGEOM.DIST($A5,$C$1,'Benchmarks by Card Role'!I$12,99,FALSE) -> 0.0064358205 | V5: =_xlfn.HYPGEOM.DIST($A5,$C$1,'Benchmarks by Card Role'!J$12,99,FALSE) -> 0.0088687744 | W5: =_xlfn.HYPGEOM.DIST($A5,$C$1,'Benchmarks by Card Role'!K$12,99,FALSE) -> 0.011838783 | X5: =_xlfn.HYPGEOM.DIST($A5,$C$1,'Benchmarks by Card Role'!L$12,99,FALSE) -> 0.015384086 | Z5: =_xlfn.HYPGEOM.DIST($A5,$C$1,'Benchmarks by Card Role'!D$22,99,FALSE) -> 0.00057123208 | AA5: =_xlfn.HYPGEOM.DIST($A5,$C$1,'Benchmarks by Card Role'!E$22,99,FALSE) -> 0.0010927918 | AB5: =_xlfn.HYPGEOM.DIST($A5,$C$1,'Benchmarks by Card Role'!F$22,99,FALSE) -> 0.0018805626 | AC5: =_xlfn.HYPGEOM.DIST($A5,$C$1,'Benchmarks by Card Role'!G$22,99,FALSE) -> 0.0029949701 | AD5: =_xlfn.HYPGEOM.DIST($A5,$C$1,'Benchmarks by Card Role'!H$22,99,FALSE) -> 0.0044948588 | AE5: =_xlfn.HYPGEOM.DIST($A5,$C$1,'Benchmarks by Card Role'!I$22,99,FALSE) -> 0.0064358205 | AF5: =_xlfn.HYPGEOM.DIST($A5,$C$1,'Benchmarks by Card Role'!J$22,99,FALSE) -> 0.0088687744 | AG5: =_xlfn.HYPGEOM.DIST($A5,$C$1,'Benchmarks by Card Role'!K$22,99,FALSE) -> 0.011838783 | AH5: =_xlfn.HYPGEOM.DIST($A5,$C$1,'Benchmarks by Card Role'!L$22,99,FALSE) -> 0.015384086 | AJ5: =_xlfn.HYPGEOM.DIST($A5,$C$1,'Benchmarks by Card Role'!D$32,99,FALSE) -> 0 | AK5: =_xlfn.HYPGEOM.DIST($A5,$C$1,'Benchmarks by Card Role'!E$32,99,FALSE) -> 0 | AL5: =_xlfn.HYPGEOM.DIST($A5,$C$1,'Benchmarks by Card Role'!F$32,99,FALSE) -> 0 | AM5: =_xlfn.HYPGEOM.DIST($A5,$C$1,'Benchmarks by Card Role'!G$32,99,FALSE) -> 0 | AN5: =_xlfn.HYPGEOM.DIST($A5,$C$1,'Benchmarks by Card Role'!H$32,99,FALSE) -> 1.8595379e-05 | AO5: =_xlfn.HYPGEOM.DIST($A5,$C$1,'Benchmarks by Card Role'!I$32,99,FALSE) -> 8.906208e-05 | AP5: =_xlfn.HYPGEOM.DIST($A5,$C$1,'Benchmarks by Card Role'!J$32,99,FALSE) -> 0.00025581661 | AQ5: =_xlfn.HYPGEOM.DIST($A5,$C$1,'Benchmarks by Card Role'!K$32,99,FALSE) -> 0.00057123208 | AR5: =_xlfn.HYPGEOM.DIST($A5,$C$1,'Benchmarks by Card Role'!L$32,99,FALSE) -> 0.0010927918 | AT5: =_xlfn.HYPGEOM.DIST($A5,$C$1,'Benchmarks by Card Role'!D$42,99,FALSE) -> 0.0018805626 | AU5: =_xlfn.HYPGEOM.DIST($A5,$C$1,'Benchmarks by Card Role'!E$42,99,FALSE) -> 0.0029949701 | AV5: =_xlfn.HYPGEOM.DIST($A5,$C$1,'Benchmarks by Card Role'!F$42,99,FALSE) -> 0.0044948588 | AW5: =_xlfn.HYPGEOM.DIST($A5,$C$1,'Benchmarks by Card Role'!G$42,99,FALSE) -> 0.0064358205 | AX5: =_xlfn.HYPGEOM.DIST($A5,$C$1,'Benchmarks by Card Role'!H$42,99,FALSE) -> 0.0088687744 | AY5: =_xlfn.HYPGEOM.DIST($A5,$C$1,'Benchmarks by Card Role'!I$42,99,FALSE) -> 0.011838783 | AZ5: =_xlfn.HYPGEOM.DIST($A5,$C$1,'Benchmarks by Card Role'!J$42,99,FALSE) -> 0.015384086 | BA5: =_xlfn.HYPGEOM.DIST($A5,$C$1,'Benchmarks by Card Role'!K$42,99,FALSE) -> 0.019535348 | BB5: =_xlfn.HYPGEOM.DIST($A5,$C$1,'Benchmarks by Card Role'!L$42,99,FALSE) -> 0.024315081
A6: 5 | B6: =_xlfn.HYPGEOM.DIST(A6,'Hypergeometric Calculator'!C$3,'Hypergeometric Calculator'!C$4,'Hypergeometric Calculator'!C$2,FALSE) -> 0.0028769914 | C6: 13 | F6: =_xlfn.HYPGEOM.DIST($A6,$C$1,'Benchmarks by Card Role'!D$2,99,FALSE) -> 0.037970888 | G6: =_xlfn.HYPGEOM.DIST($A6,$C$1,'Benchmarks by Card Role'!E$2,99,FALSE) -> 0.043612277 | H6: =_xlfn.HYPGEOM.DIST($A6,$C$1,'Benchmarks by Card Role'!F$2,99,FALSE) -> 0.049738416 | I6: =_xlfn.HYPGEOM.DIST($A6,$C$1,'Benchmarks by Card Role'!G$2,99,FALSE) -> 0.056348532 | J6: =_xlfn.HYPGEOM.DIST($A6,$C$1,'Benchmarks by Card Role'!H$2,99,FALSE) -> 0.063437153 | K6: =_xlfn.HYPGEOM.DIST($A6,$C$1,'Benchmarks by Card Role'!I$2,99,FALSE) -> 0.07099393 | L6: =_xlfn.HYPGEOM.DIST($A6,$C$1,'Benchmarks by Card Role'!J$2,99,FALSE) -> 0.079003502 | M6: =_xlfn.HYPGEOM.DIST($A6,$C$1,'Benchmarks by Card Role'!K$2,99,FALSE) -> 0.087445408 | N6: =_xlfn.HYPGEOM.DIST($A6,$C$1,'Benchmarks by Card Role'!L$2,99,FALSE) -> 0.096294051 | P6: =_xlfn.HYPGEOM.DIST($A6,$C$1,'Benchmarks by Card Role'!D$12,99,FALSE) -> 1.5404011e-05 | Q6: =_xlfn.HYPGEOM.DIST($A6,$C$1,'Benchmarks by Card Role'!E$12,99,FALSE) -> 3.9737884e-05 | R6: =_xlfn.HYPGEOM.DIST($A6,$C$1,'Benchmarks by Card Role'!F$12,99,FALSE) -> 8.6462648e-05 | S6: =_xlfn.HYPGEOM.DIST($A6,$C$1,'Benchmarks by Card Role'!G$12,99,FALSE) -> 0.00016716112 | T6: =_xlfn.HYPGEOM.DIST($A6,$C$1,'Benchmarks by Card Role'!H$12,99,FALSE) -> 0.00029613187 | U6: =_xlfn.HYPGEOM.DIST($A6,$C$1,'Benchmarks by Card Role'!I$12,99,FALSE) -> 0.00049034823 | V6: =_xlfn.HYPGEOM.DIST($A6,$C$1,'Benchmarks by Card Role'!J$12,99,FALSE) -> 0.00076933946 | W6: =_xlfn.HYPGEOM.DIST($A6,$C$1,'Benchmarks by Card Role'!K$12,99,FALSE) -> 0.0011550032 | X6: =_xlfn.HYPGEOM.DIST($A6,$C$1,'Benchmarks by Card Role'!L$12,99,FALSE) -> 0.0016713575 | Z6: =_xlfn.HYPGEOM.DIST($A6,$C$1,'Benchmarks by Card Role'!D$22,99,FALSE) -> 1.5404011e-05 | AA6: =_xlfn.HYPGEOM.DIST($A6,$C$1,'Benchmarks by Card Role'!E$22,99,FALSE) -> 3.9737884e-05 | AB6: =_xlfn.HYPGEOM.DIST($A6,$C$1,'Benchmarks by Card Role'!F$22,99,FALSE) -> 8.6462648e-05 | AC6: =_xlfn.HYPGEOM.DIST($A6,$C$1,'Benchmarks by Card Role'!G$22,99,FALSE) -> 0.00016716112 | AD6: =_xlfn.HYPGEOM.DIST($A6,$C$1,'Benchmarks by Card Role'!H$22,99,FALSE) -> 0.00029613187 | AE6: =_xlfn.HYPGEOM.DIST($A6,$C$1,'Benchmarks by Card Role'!I$22,99,FALSE) -> 0.00049034823 | AF6: =_xlfn.HYPGEOM.DIST($A6,$C$1,'Benchmarks by Card Role'!J$22,99,FALSE) -> 0.00076933946 | AG6: =_xlfn.HYPGEOM.DIST($A6,$C$1,'Benchmarks by Card Role'!K$22,99,FALSE) -> 0.0011550032 | AH6: =_xlfn.HYPGEOM.DIST($A6,$C$1,'Benchmarks by Card Role'!L$22,99,FALSE) -> 0.0016713575 | AJ6: =_xlfn.HYPGEOM.DIST($A6,$C$1,'Benchmarks by Card Role'!D$32,99,FALSE) -> 0 | AK6: =_xlfn.HYPGEOM.DIST($A6,$C$1,'Benchmarks by Card Role'!E$32,99,FALSE) -> 0 | AL6: =_xlfn.HYPGEOM.DIST($A6,$C$1,'Benchmarks by Card Role'!F$32,99,FALSE) -> 0 | AM6: =_xlfn.HYPGEOM.DIST($A6,$C$1,'Benchmarks by Card Role'!G$32,99,FALSE) -> 0 | AN6: =_xlfn.HYPGEOM.DIST($A6,$C$1,'Benchmarks by Card Role'!H$32,99,FALSE) -> 0 | AO6: =_xlfn.HYPGEOM.DIST($A6,$C$1,'Benchmarks by Card Role'!I$32,99,FALSE) -> 7.8296334e-07 | AP6: =_xlfn.HYPGEOM.DIST($A6,$C$1,'Benchmarks by Card Role'!J$32,99,FALSE) -> 4.5478509e-06 | AQ6: =_xlfn.HYPGEOM.DIST($A6,$C$1,'Benchmarks by Card Role'!K$32,99,FALSE) -> 1.5404011e-05 | AR6: =_xlfn.HYPGEOM.DIST($A6,$C$1,'Benchmarks by Card Role'!L$32,99,FALSE) -> 3.9737884e-05 | AT6: =_xlfn.HYPGEOM.DIST($A6,$C$1,'Benchmarks by Card Role'!D$42,99,FALSE) -> 8.6462648e-05 | AU6: =_xlfn.HYPGEOM.DIST($A6,$C$1,'Benchmarks by Card Role'!E$42,99,FALSE) -> 0.00016716112 | AV6: =_xlfn.HYPGEOM.DIST($A6,$C$1,'Benchmarks by Card Role'!F$42,99,FALSE) -> 0.00029613187 | AW6: =_xlfn.HYPGEOM.DIST($A6,$C$1,'Benchmarks by Card Role'!G$42,99,FALSE) -> 0.00049034823 | AX6: =_xlfn.HYPGEOM.DIST($A6,$C$1,'Benchmarks by Card Role'!H$42,99,FALSE) -> 0.00076933946 | AY6: =_xlfn.HYPGEOM.DIST($A6,$C$1,'Benchmarks by Card Role'!I$42,99,FALSE) -> 0.0011550032 | AZ6: =_xlfn.HYPGEOM.DIST($A6,$C$1,'Benchmarks by Card Role'!J$42,99,FALSE) -> 0.0016713575 | BA6: =_xlfn.HYPGEOM.DIST($A6,$C$1,'Benchmarks by Card Role'!K$42,99,FALSE) -> 0.0023442417 | BB6: =_xlfn.HYPGEOM.DIST($A6,$C$1,'Benchmarks by Card Role'!L$42,99,FALSE) -> 0.0032009727
A7: 6 | F7: =_xlfn.HYPGEOM.DIST($A7,$C$1,'Benchmarks by Card Role'!D$2,99,FALSE) -> 0.0067007449 | G7: =_xlfn.HYPGEOM.DIST($A7,$C$1,'Benchmarks by Card Role'!E$2,99,FALSE) -> 0.0081366188 | H7: =_xlfn.HYPGEOM.DIST($A7,$C$1,'Benchmarks by Card Role'!F$2,99,FALSE) -> 0.0097969607 | I7: =_xlfn.HYPGEOM.DIST($A7,$C$1,'Benchmarks by Card Role'!G$2,99,FALSE) -> 0.011703157 | J7: =_xlfn.HYPGEOM.DIST($A7,$C$1,'Benchmarks by Card Role'!H$2,99,FALSE) -> 0.013876877 | K7: =_xlfn.HYPGEOM.DIST($A7,$C$1,'Benchmarks by Card Role'!I$2,99,FALSE) -> 0.016339873 | L7: =_xlfn.HYPGEOM.DIST($A7,$C$1,'Benchmarks by Card Role'!J$2,99,FALSE) -> 0.01911375 | M7: =_xlfn.HYPGEOM.DIST($A7,$C$1,'Benchmarks by Card Role'!K$2,99,FALSE) -> 0.022219735 | N7: =_xlfn.HYPGEOM.DIST($A7,$C$1,'Benchmarks by Card Role'!L$2,99,FALSE) -> 0.025678413 | P7: =_xlfn.HYPGEOM.DIST($A7,$C$1,'Benchmarks by Card Role'!D$12,99,FALSE) -> 1.7115568e-07 | Q7: =_xlfn.HYPGEOM.DIST($A7,$C$1,'Benchmarks by Card Role'!E$12,99,FALSE) -> 6.6973962e-07 | R7: =_xlfn.HYPGEOM.DIST($A7,$C$1,'Benchmarks by Card Role'!F$12,99,FALSE) -> 1.9650602e-06 | S7: =_xlfn.HYPGEOM.DIST($A7,$C$1,'Benchmarks by Card Role'!G$12,99,FALSE) -> 4.8034805e-06 | T7: =_xlfn.HYPGEOM.DIST($A7,$C$1,'Benchmarks by Card Role'!H$12,99,FALSE) -> 1.0330182e-05 | U7: =_xlfn.HYPGEOM.DIST($A7,$C$1,'Benchmarks by Card Role'!I$12,99,FALSE) -> 2.0190809e-05 | V7: =_xlfn.HYPGEOM.DIST($A7,$C$1,'Benchmarks by Card Role'!J$12,99,FALSE) -> 3.6635213e-05 | W7: =_xlfn.HYPGEOM.DIST($A7,$C$1,'Benchmarks by Card Role'!K$12,99,FALSE) -> 6.2620654e-05 | X7: =_xlfn.HYPGEOM.DIST($A7,$C$1,'Benchmarks by Card Role'!L$12,99,FALSE) -> 0.00010191204 | Z7: =_xlfn.HYPGEOM.DIST($A7,$C$1,'Benchmarks by Card Role'!D$22,99,FALSE) -> 1.7115568e-07 | AA7: =_xlfn.HYPGEOM.DIST($A7,$C$1,'Benchmarks by Card Role'!E$22,99,FALSE) -> 6.6973962e-07 | AB7: =_xlfn.HYPGEOM.DIST($A7,$C$1,'Benchmarks by Card Role'!F$22,99,FALSE) -> 1.9650602e-06 | AC7: =_xlfn.HYPGEOM.DIST($A7,$C$1,'Benchmarks by Card Role'!G$22,99,FALSE) -> 4.8034805e-06 | AD7: =_xlfn.HYPGEOM.DIST($A7,$C$1,'Benchmarks by Card Role'!H$22,99,FALSE) -> 1.0330182e-05 | AE7: =_xlfn.HYPGEOM.DIST($A7,$C$1,'Benchmarks by Card Role'!I$22,99,FALSE) -> 2.0190809e-05 | AF7: =_xlfn.HYPGEOM.DIST($A7,$C$1,'Benchmarks by Card Role'!J$22,99,FALSE) -> 3.6635213e-05 | AG7: =_xlfn.HYPGEOM.DIST($A7,$C$1,'Benchmarks by Card Role'!K$22,99,FALSE) -> 6.2620654e-05 | AH7: =_xlfn.HYPGEOM.DIST($A7,$C$1,'Benchmarks by Card Role'!L$22,99,FALSE) -> 0.00010191204 | AJ7: =_xlfn.HYPGEOM.DIST($A7,$C$1,'Benchmarks by Card Role'!D$32,99,FALSE) -> 0 | AK7: =_xlfn.HYPGEOM.DIST($A7,$C$1,'Benchmarks by Card Role'!E$32,99,FALSE) -> 0 | AL7: =_xlfn.HYPGEOM.DIST($A7,$C$1,'Benchmarks by Card Role'!F$32,99,FALSE) -> 0 | AM7: =_xlfn.HYPGEOM.DIST($A7,$C$1,'Benchmarks by Card Role'!G$32,99,FALSE) -> 0 | AN7: =_xlfn.HYPGEOM.DIST($A7,$C$1,'Benchmarks by Card Role'!H$32,99,FALSE) -> 0 | AO7: =_xlfn.HYPGEOM.DIST($A7,$C$1,'Benchmarks by Card Role'!I$32,99,FALSE) -> 0 | AP7: =_xlfn.HYPGEOM.DIST($A7,$C$1,'Benchmarks by Card Role'!J$32,99,FALSE) -> 2.4988192e-08 | AQ7: =_xlfn.HYPGEOM.DIST($A7,$C$1,'Benchmarks by Card Role'!K$32,99,FALSE) -> 1.7115568e-07 | AR7: =_xlfn.HYPGEOM.DIST($A7,$C$1,'Benchmarks by Card Role'!L$32,99,FALSE) -> 6.6973962e-07 | AT7: =_xlfn.HYPGEOM.DIST($A7,$C$1,'Benchmarks by Card Role'!D$42,99,FALSE) -> 1.9650602e-06 | AU7: =_xlfn.HYPGEOM.DIST($A7,$C$1,'Benchmarks by Card Role'!E$42,99,FALSE) -> 4.8034805e-06 | AV7: =_xlfn.HYPGEOM.DIST($A7,$C$1,'Benchmarks by Card Role'!F$42,99,FALSE) -> 1.0330182e-05 | AW7: =_xlfn.HYPGEOM.DIST($A7,$C$1,'Benchmarks by Card Role'!G$42,99,FALSE) -> 2.0190809e-05 | AX7: =_xlfn.HYPGEOM.DIST($A7,$C$1,'Benchmarks by Card Role'!H$42,99,FALSE) -> 3.6635213e-05 | AY7: =_xlfn.HYPGEOM.DIST($A7,$C$1,'Benchmarks by Card Role'!I$42,99,FALSE) -> 6.2620654e-05 | AZ7: =_xlfn.HYPGEOM.DIST($A7,$C$1,'Benchmarks by Card Role'!J$42,99,FALSE) -> 0.00010191204 | BA7: =_xlfn.HYPGEOM.DIST($A7,$C$1,'Benchmarks by Card Role'!K$42,99,FALSE) -> 0.00015917691 | BB7: =_xlfn.HYPGEOM.DIST($A7,$C$1,'Benchmarks by Card Role'!L$42,99,FALSE) -> 0.00024007295
A8: 7 | F8: =_xlfn.HYPGEOM.DIST($A8,$C$1,'Benchmarks by Card Role'!D$2,99,FALSE) -> 0.00063816618 | G8: =_xlfn.HYPGEOM.DIST($A8,$C$1,'Benchmarks by Card Role'!E$2,99,FALSE) -> 0.00082049937 | H8: =_xlfn.HYPGEOM.DIST($A8,$C$1,'Benchmarks by Card Role'!F$2,99,FALSE) -> 0.0010444521 | I8: =_xlfn.HYPGEOM.DIST($A8,$C$1,'Benchmarks by Card Role'!G$2,99,FALSE) -> 0.0013172384 | J8: =_xlfn.HYPGEOM.DIST($A8,$C$1,'Benchmarks by Card Role'!H$2,99,FALSE) -> 0.0016469261 | K8: =_xlfn.HYPGEOM.DIST($A8,$C$1,'Benchmarks by Card Role'!I$2,99,FALSE) -> 0.0020424841 | L8: =_xlfn.HYPGEOM.DIST($A8,$C$1,'Benchmarks by Card Role'!J$2,99,FALSE) -> 0.0025138266 | M8: =_xlfn.HYPGEOM.DIST($A8,$C$1,'Benchmarks by Card Role'!K$2,99,FALSE) -> 0.0030718527 | N8: =_xlfn.HYPGEOM.DIST($A8,$C$1,'Benchmarks by Card Role'!L$2,99,FALSE) -> 0.0037284816 | P8: =_xlfn.HYPGEOM.DIST($A8,$C$1,'Benchmarks by Card Role'!D$12,99,FALSE) -> 5.3738047e-10 | Q8: =_xlfn.HYPGEOM.DIST($A8,$C$1,'Benchmarks by Card Role'!E$12,99,FALSE) -> 4.252315e-09 | R8: =_xlfn.HYPGEOM.DIST($A8,$C$1,'Benchmarks by Card Role'!F$12,99,FALSE) -> 1.8925138e-08 | S8: =_xlfn.HYPGEOM.DIST($A8,$C$1,'Benchmarks by Card Role'!G$12,99,FALSE) -> 6.2382863e-08 | T8: =_xlfn.HYPGEOM.DIST($A8,$C$1,'Benchmarks by Card Role'!H$12,99,FALSE) -> 1.6962531e-07 | U8: =_xlfn.HYPGEOM.DIST($A8,$C$1,'Benchmarks by Card Role'!I$12,99,FALSE) -> 4.0247461e-07 | V8: =_xlfn.HYPGEOM.DIST($A8,$C$1,'Benchmarks by Card Role'!J$12,99,FALSE) -> 8.62005e-07 | W8: =_xlfn.HYPGEOM.DIST($A8,$C$1,'Benchmarks by Card Role'!K$12,99,FALSE) -> 1.7039634e-06 | X8: =_xlfn.HYPGEOM.DIST($A8,$C$1,'Benchmarks by Card Role'!L$12,99,FALSE) -> 3.1573439e-06 | Z8: =_xlfn.HYPGEOM.DIST($A8,$C$1,'Benchmarks by Card Role'!D$22,99,FALSE) -> 5.3738047e-10 | AA8: =_xlfn.HYPGEOM.DIST($A8,$C$1,'Benchmarks by Card Role'!E$22,99,FALSE) -> 4.252315e-09 | AB8: =_xlfn.HYPGEOM.DIST($A8,$C$1,'Benchmarks by Card Role'!F$22,99,FALSE) -> 1.8925138e-08 | AC8: =_xlfn.HYPGEOM.DIST($A8,$C$1,'Benchmarks by Card Role'!G$22,99,FALSE) -> 6.2382863e-08 | AD8: =_xlfn.HYPGEOM.DIST($A8,$C$1,'Benchmarks by Card Role'!H$22,99,FALSE) -> 1.6962531e-07 | AE8: =_xlfn.HYPGEOM.DIST($A8,$C$1,'Benchmarks by Card Role'!I$22,99,FALSE) -> 4.0247461e-07 | AF8: =_xlfn.HYPGEOM.DIST($A8,$C$1,'Benchmarks by Card Role'!J$22,99,FALSE) -> 8.62005e-07 | AG8: =_xlfn.HYPGEOM.DIST($A8,$C$1,'Benchmarks by Card Role'!K$22,99,FALSE) -> 1.7039634e-06 | AH8: =_xlfn.HYPGEOM.DIST($A8,$C$1,'Benchmarks by Card Role'!L$22,99,FALSE) -> 3.1573439e-06 | AJ8: =_xlfn.HYPGEOM.DIST($A8,$C$1,'Benchmarks by Card Role'!D$32,99,FALSE) -> 0 | AK8: =_xlfn.HYPGEOM.DIST($A8,$C$1,'Benchmarks by Card Role'!E$32,99,FALSE) -> 0 | AL8: =_xlfn.HYPGEOM.DIST($A8,$C$1,'Benchmarks by Card Role'!F$32,99,FALSE) -> 0 | AM8: =_xlfn.HYPGEOM.DIST($A8,$C$1,'Benchmarks by Card Role'!G$32,99,FALSE) -> 0 | AN8: =_xlfn.HYPGEOM.DIST($A8,$C$1,'Benchmarks by Card Role'!H$32,99,FALSE) -> 0 | AO8: =_xlfn.HYPGEOM.DIST($A8,$C$1,'Benchmarks by Card Role'!I$32,99,FALSE) -> 0 | AP8: =_xlfn.HYPGEOM.DIST($A8,$C$1,'Benchmarks by Card Role'!J$32,99,FALSE) -> 0 | AQ8: =_xlfn.HYPGEOM.DIST($A8,$C$1,'Benchmarks by Card Role'!K$32,99,FALSE) -> 5.3738047e-10 | AR8: =_xlfn.HYPGEOM.DIST($A8,$C$1,'Benchmarks by Card Role'!L$32,99,FALSE) -> 4.252315e-09 | AT8: =_xlfn.HYPGEOM.DIST($A8,$C$1,'Benchmarks by Card Role'!D$42,99,FALSE) -> 1.8925138e-08 | AU8: =_xlfn.HYPGEOM.DIST($A8,$C$1,'Benchmarks by Card Role'!E$42,99,FALSE) -> 6.2382863e-08 | AV8: =_xlfn.HYPGEOM.DIST($A8,$C$1,'Benchmarks by Card Role'!F$42,99,FALSE) -> 1.6962531e-07 | AW8: =_xlfn.HYPGEOM.DIST($A8,$C$1,'Benchmarks by Card Role'!G$42,99,FALSE) -> 4.0247461e-07 | AX8: =_xlfn.HYPGEOM.DIST($A8,$C$1,'Benchmarks by Card Role'!H$42,99,FALSE) -> 8.62005e-07 | AY8: =_xlfn.HYPGEOM.DIST($A8,$C$1,'Benchmarks by Card Role'!I$42,99,FALSE) -> 1.7039634e-06 | AZ8: =_xlfn.HYPGEOM.DIST($A8,$C$1,'Benchmarks by Card Role'!J$42,99,FALSE) -> 3.1573439e-06 | BA8: =_xlfn.HYPGEOM.DIST($A8,$C$1,'Benchmarks by Card Role'!K$42,99,FALSE) -> 5.5462337e-06 | BB8: =_xlfn.HYPGEOM.DIST($A8,$C$1,'Benchmarks by Card Role'!L$42,99,FALSE) -> 9.3149998e-06
A9: 8 | F9: =_xlfn.HYPGEOM.DIST($A9,$C$1,'Benchmarks by Card Role'!D$2,99,FALSE) -> 2.5070814e-05 | G9: =_xlfn.HYPGEOM.DIST($A9,$C$1,'Benchmarks by Card Role'!E$2,99,FALSE) -> 3.4187474e-05 | H9: =_xlfn.HYPGEOM.DIST($A9,$C$1,'Benchmarks by Card Role'!F$2,99,FALSE) -> 4.6078769e-05 | I9: =_xlfn.HYPGEOM.DIST($A9,$C$1,'Benchmarks by Card Role'!G$2,99,FALSE) -> 6.1438359e-05 | J9: =_xlfn.HYPGEOM.DIST($A9,$C$1,'Benchmarks by Card Role'!H$2,99,FALSE) -> 8.1098633e-05 | K9: =_xlfn.HYPGEOM.DIST($A9,$C$1,'Benchmarks by Card Role'!I$2,99,FALSE) -> 0.00010605206 | L9: =_xlfn.HYPGEOM.DIST($A9,$C$1,'Benchmarks by Card Role'!J$2,99,FALSE) -> 0.00013747489 | M9: =_xlfn.HYPGEOM.DIST($A9,$C$1,'Benchmarks by Card Role'!K$2,99,FALSE) -> 0.00017675343 | N9: =_xlfn.HYPGEOM.DIST($A9,$C$1,'Benchmarks by Card Role'!L$2,99,FALSE) -> 0.000225513 | P9: =_xlfn.HYPGEOM.DIST($A9,$C$1,'Benchmarks by Card Role'!D$12,99,FALSE) -> 0 | Q9: =_xlfn.HYPGEOM.DIST($A9,$C$1,'Benchmarks by Card Role'!E$12,99,FALSE) -> 5.8410921e-12 | R9: =_xlfn.HYPGEOM.DIST($A9,$C$1,'Benchmarks by Card Role'!F$12,99,FALSE) -> 5.2569829e-11 | S9: =_xlfn.HYPGEOM.DIST($A9,$C$1,'Benchmarks by Card Role'!G$12,99,FALSE) -> 2.6284914e-10 | T9: =_xlfn.HYPGEOM.DIST($A9,$C$1,'Benchmarks by Card Role'!H$12,99,FALSE) -> 9.6378019e-10 | U9: =_xlfn.HYPGEOM.DIST($A9,$C$1,'Benchmarks by Card Role'!I$12,99,FALSE) -> 2.8913406e-09 | V9: =_xlfn.HYPGEOM.DIST($A9,$C$1,'Benchmarks by Card Role'!J$12,99,FALSE) -> 7.5174855e-09 | W9: =_xlfn.HYPGEOM.DIST($A9,$C$1,'Benchmarks by Card Role'!K$12,99,FALSE) -> 1.7540799e-08 | X9: =_xlfn.HYPGEOM.DIST($A9,$C$1,'Benchmarks by Card Role'!L$12,99,FALSE) -> 3.7587427e-08 | Z9: =_xlfn.HYPGEOM.DIST($A9,$C$1,'Benchmarks by Card Role'!D$22,99,FALSE) -> 0 | AA9: =_xlfn.HYPGEOM.DIST($A9,$C$1,'Benchmarks by Card Role'!E$22,99,FALSE) -> 5.8410921e-12 | AB9: =_xlfn.HYPGEOM.DIST($A9,$C$1,'Benchmarks by Card Role'!F$22,99,FALSE) -> 5.2569829e-11 | AC9: =_xlfn.HYPGEOM.DIST($A9,$C$1,'Benchmarks by Card Role'!G$22,99,FALSE) -> 2.6284914e-10 | AD9: =_xlfn.HYPGEOM.DIST($A9,$C$1,'Benchmarks by Card Role'!H$22,99,FALSE) -> 9.6378019e-10 | AE9: =_xlfn.HYPGEOM.DIST($A9,$C$1,'Benchmarks by Card Role'!I$22,99,FALSE) -> 2.8913406e-09 | AF9: =_xlfn.HYPGEOM.DIST($A9,$C$1,'Benchmarks by Card Role'!J$22,99,FALSE) -> 7.5174855e-09 | AG9: =_xlfn.HYPGEOM.DIST($A9,$C$1,'Benchmarks by Card Role'!K$22,99,FALSE) -> 1.7540799e-08 | AH9: =_xlfn.HYPGEOM.DIST($A9,$C$1,'Benchmarks by Card Role'!L$22,99,FALSE) -> 3.7587427e-08 | AJ9: =_xlfn.HYPGEOM.DIST($A9,$C$1,'Benchmarks by Card Role'!D$32,99,FALSE) -> 0 | AK9: =_xlfn.HYPGEOM.DIST($A9,$C$1,'Benchmarks by Card Role'!E$32,99,FALSE) -> 0 | AL9: =_xlfn.HYPGEOM.DIST($A9,$C$1,'Benchmarks by Card Role'!F$32,99,FALSE) -> 0 | AM9: =_xlfn.HYPGEOM.DIST($A9,$C$1,'Benchmarks by Card Role'!G$32,99,FALSE) -> 0 | AN9: =_xlfn.HYPGEOM.DIST($A9,$C$1,'Benchmarks by Card Role'!H$32,99,FALSE) -> 0 | AO9: =_xlfn.HYPGEOM.DIST($A9,$C$1,'Benchmarks by Card Role'!I$32,99,FALSE) -> 0 | AP9: =_xlfn.HYPGEOM.DIST($A9,$C$1,'Benchmarks by Card Role'!J$32,99,FALSE) -> 0 | AQ9: =_xlfn.HYPGEOM.DIST($A9,$C$1,'Benchmarks by Card Role'!K$32,99,FALSE) -> 0 | AR9: =_xlfn.HYPGEOM.DIST($A9,$C$1,'Benchmarks by Card Role'!L$32,99,FALSE) -> 5.8410921e-12 | AT9: =_xlfn.HYPGEOM.DIST($A9,$C$1,'Benchmarks by Card Role'!D$42,99,FALSE) -> 5.2569829e-11 | AU9: =_xlfn.HYPGEOM.DIST($A9,$C$1,'Benchmarks by Card Role'!E$42,99,FALSE) -> 2.6284914e-10 | AV9: =_xlfn.HYPGEOM.DIST($A9,$C$1,'Benchmarks by Card Role'!F$42,99,FALSE) -> 9.6378019e-10 | AW9: =_xlfn.HYPGEOM.DIST($A9,$C$1,'Benchmarks by Card Role'!G$42,99,FALSE) -> 2.8913406e-09 | AX9: =_xlfn.HYPGEOM.DIST($A9,$C$1,'Benchmarks by Card Role'!H$42,99,FALSE) -> 7.5174855e-09 | AY9: =_xlfn.HYPGEOM.DIST($A9,$C$1,'Benchmarks by Card Role'!I$42,99,FALSE) -> 1.7540799e-08 | AZ9: =_xlfn.HYPGEOM.DIST($A9,$C$1,'Benchmarks by Card Role'!J$42,99,FALSE) -> 3.7587427e-08 | BA9: =_xlfn.HYPGEOM.DIST($A9,$C$1,'Benchmarks by Card Role'!K$42,99,FALSE) -> 7.5174855e-08 | BB9: =_xlfn.HYPGEOM.DIST($A9,$C$1,'Benchmarks by Card Role'!L$42,99,FALSE) -> 1.4199695e-07
F10: =SUM(F1*$A$1,F2*$A$2,F3*$A$3,F4*$A$4,F5*$A$5,F6*$A$6,F7*$A$7,F8*$A$8,F9*$A$9) -> 2.3434343 | G10: =SUM(G1*$A$1,G2*$A$2,G3*$A$3,G4*$A$4,G5*$A$5,G6*$A$6,G7*$A$7,G8*$A$8,G9*$A$9) -> 2.4242424 | H10: =SUM(H1*$A$1,H2*$A$2,H3*$A$3,H4*$A$4,H5*$A$5,H6*$A$6,H7*$A$7,H8*$A$8,H9*$A$9) -> 2.5050505 | I10: =SUM(I1*$A$1,I2*$A$2,I3*$A$3,I4*$A$4,I5*$A$5,I6*$A$6,I7*$A$7,I8*$A$8,I9*$A$9) -> 2.5858586 | J10: =SUM(J1*$A$1,J2*$A$2,J3*$A$3,J4*$A$4,J5*$A$5,J6*$A$6,J7*$A$7,J8*$A$8,J9*$A$9) -> 2.6666667 | K10: =SUM(K1*$A$1,K2*$A$2,K3*$A$3,K4*$A$4,K5*$A$5,K6*$A$6,K7*$A$7,K8*$A$8,K9*$A$9) -> 2.7474747 | L10: =SUM(L1*$A$1,L2*$A$2,L3*$A$3,L4*$A$4,L5*$A$5,L6*$A$6,L7*$A$7,L8*$A$8,L9*$A$9) -> 2.8282828 | M10: =SUM(M1*$A$1,M2*$A$2,M3*$A$3,M4*$A$4,M5*$A$5,M6*$A$6,M7*$A$7,M8*$A$8,M9*$A$9) -> 2.9090909 | N10: =SUM(N1*$A$1,N2*$A$2,N3*$A$3,N4*$A$4,N5*$A$5,N6*$A$6,N7*$A$7,N8*$A$8,N9*$A$9) -> 2.989899 | P10: =SUM(P1*$A$1,P2*$A$2,P3*$A$3,P4*$A$4,P5*$A$5,P6*$A$6,P7*$A$7,P8*$A$8,P9*$A$9) -> 0.56565657 | Q10: =SUM(Q1*$A$1,Q2*$A$2,Q3*$A$3,Q4*$A$4,Q5*$A$5,Q6*$A$6,Q7*$A$7,Q8*$A$8,Q9*$A$9) -> 0.64646465 | R10: =SUM(R1*$A$1,R2*$A$2,R3*$A$3,R4*$A$4,R5*$A$5,R6*$A$6,R7*$A$7,R8*$A$8,R9*$A$9) -> 0.72727273 | S10: =SUM(S1*$A$1,S2*$A$2,S3*$A$3,S4*$A$4,S5*$A$5,S6*$A$6,S7*$A$7,S8*$A$8,S9*$A$9) -> 0.80808081 | T10: =SUM(T1*$A$1,T2*$A$2,T3*$A$3,T4*$A$4,T5*$A$5,T6*$A$6,T7*$A$7,T8*$A$8,T9*$A$9) -> 0.88888889 | U10: =SUM(U1*$A$1,U2*$A$2,U3*$A$3,U4*$A$4,U5*$A$5,U6*$A$6,U7*$A$7,U8*$A$8,U9*$A$9) -> 0.96969697 | V10: =SUM(V1*$A$1,V2*$A$2,V3*$A$3,V4*$A$4,V5*$A$5,V6*$A$6,V7*$A$7,V8*$A$8,V9*$A$9) -> 1.0505051 | W10: =SUM(W1*$A$1,W2*$A$2,W3*$A$3,W4*$A$4,W5*$A$5,W6*$A$6,W7*$A$7,W8*$A$8,W9*$A$9) -> 1.1313131 | X10: =SUM(X1*$A$1,X2*$A$2,X3*$A$3,X4*$A$4,X5*$A$5,X6*$A$6,X7*$A$7,X8*$A$8,X9*$A$9) -> 1.2121212 | Z10: =SUM(Z1*$A$1,Z2*$A$2,Z3*$A$3,Z4*$A$4,Z5*$A$5,Z6*$A$6,Z7*$A$7,Z8*$A$8,Z9*$A$9) -> 0.56565657 | AA10: =SUM(AA1*$A$1,AA2*$A$2,AA3*$A$3,AA4*$A$4,AA5*$A$5,AA6*$A$6,AA7*$A$7,AA8*$A$8,AA9*$A$9) -> 0.64646465 | AB10: =SUM(AB1*$A$1,AB2*$A$2,AB3*$A$3,AB4*$A$4,AB5*$A$5,AB6*$A$6,AB7*$A$7,AB8*$A$8,AB9*$A$9) -> 0.72727273 | AC10: =SUM(AC1*$A$1,AC2*$A$2,AC3*$A$3,AC4*$A$4,AC5*$A$5,AC6*$A$6,AC7*$A$7,AC8*$A$8,AC9*$A$9) -> 0.80808081 | AD10: =SUM(AD1*$A$1,AD2*$A$2,AD3*$A$3,AD4*$A$4,AD5*$A$5,AD6*$A$6,AD7*$A$7,AD8*$A$8,AD9*$A$9) -> 0.88888889 | AE10: =SUM(AE1*$A$1,AE2*$A$2,AE3*$A$3,AE4*$A$4,AE5*$A$5,AE6*$A$6,AE7*$A$7,AE8*$A$8,AE9*$A$9) -> 0.96969697 | AF10: =SUM(AF1*$A$1,AF2*$A$2,AF3*$A$3,AF4*$A$4,AF5*$A$5,AF6*$A$6,AF7*$A$7,AF8*$A$8,AF9*$A$9) -> 1.0505051 | AG10: =SUM(AG1*$A$1,AG2*$A$2,AG3*$A$3,AG4*$A$4,AG5*$A$5,AG6*$A$6,AG7*$A$7,AG8*$A$8,AG9*$A$9) -> 1.1313131 | AH10: =SUM(AH1*$A$1,AH2*$A$2,AH3*$A$3,AH4*$A$4,AH5*$A$5,AH6*$A$6,AH7*$A$7,AH8*$A$8,AH9*$A$9) -> 1.2121212 | AJ10: =SUM(AJ1*$A$1,AJ2*$A$2,AJ3*$A$3,AJ4*$A$4,AJ5*$A$5,AJ6*$A$6,AJ7*$A$7,AJ8*$A$8,AJ9*$A$9) -> 0 | AK10: =SUM(AK1*$A$1,AK2*$A$2,AK3*$A$3,AK4*$A$4,AK5*$A$5,AK6*$A$6,AK7*$A$7,AK8*$A$8,AK9*$A$9) -> 0.080808081 | AL10: =SUM(AL1*$A$1,AL2*$A$2,AL3*$A$3,AL4*$A$4,AL5*$A$5,AL6*$A$6,AL7*$A$7,AL8*$A$8,AL9*$A$9) -> 0.16161616 | AM10: =SUM(AM1*$A$1,AM2*$A$2,AM3*$A$3,AM4*$A$4,AM5*$A$5,AM6*$A$6,AM7*$A$7,AM8*$A$8,AM9*$A$9) -> 0.24242424 | AN10: =SUM(AN1*$A$1,AN2*$A$2,AN3*$A$3,AN4*$A$4,AN5*$A$5,AN6*$A$6,AN7*$A$7,AN8*$A$8,AN9*$A$9) -> 0.32323232 | AO10: =SUM(AO1*$A$1,AO2*$A$2,AO3*$A$3,AO4*$A$4,AO5*$A$5,AO6*$A$6,AO7*$A$7,AO8*$A$8,AO9*$A$9) -> 0.4040404 | AP10: =SUM(AP1*$A$1,AP2*$A$2,AP3*$A$3,AP4*$A$4,AP5*$A$5,AP6*$A$6,AP7*$A$7,AP8*$A$8,AP9*$A$9) -> 0.48484848 | AQ10: =SUM(AQ1*$A$1,AQ2*$A$2,AQ3*$A$3,AQ4*$A$4,AQ5*$A$5,AQ6*$A$6,AQ7*$A$7,AQ8*$A$8,AQ9*$A$9) -> 0.56565657 | AR10: =SUM(AR1*$A$1,AR2*$A$2,AR3*$A$3,AR4*$A$4,AR5*$A$5,AR6*$A$6,AR7*$A$7,AR8*$A$8,AR9*$A$9) -> 0.64646465 | AT10: =SUM(AT1*$A$1,AT2*$A$2,AT3*$A$3,AT4*$A$4,AT5*$A$5,AT6*$A$6,AT7*$A$7,AT8*$A$8,AT9*$A$9) -> 0.72727273 | AU10: =SUM(AU1*$A$1,AU2*$A$2,AU3*$A$3,AU4*$A$4,AU5*$A$5,AU6*$A$6,AU7*$A$7,AU8*$A$8,AU9*$A$9) -> 0.80808081 | AV10: =SUM(AV1*$A$1,AV2*$A$2,AV3*$A$3,AV4*$A$4,AV5*$A$5,AV6*$A$6,AV7*$A$7,AV8*$A$8,AV9*$A$9) -> 0.88888889 | AW10: =SUM(AW1*$A$1,AW2*$A$2,AW3*$A$3,AW4*$A$4,AW5*$A$5,AW6*$A$6,AW7*$A$7,AW8*$A$8,AW9*$A$9) -> 0.96969697 | AX10: =SUM(AX1*$A$1,AX2*$A$2,AX3*$A$3,AX4*$A$4,AX5*$A$5,AX6*$A$6,AX7*$A$7,AX8*$A$8,AX9*$A$9) -> 1.0505051 | AY10: =SUM(AY1*$A$1,AY2*$A$2,AY3*$A$3,AY4*$A$4,AY5*$A$5,AY6*$A$6,AY7*$A$7,AY8*$A$8,AY9*$A$9) -> 1.1313131 | AZ10: =SUM(AZ1*$A$1,AZ2*$A$2,AZ3*$A$3,AZ4*$A$4,AZ5*$A$5,AZ6*$A$6,AZ7*$A$7,AZ8*$A$8,AZ9*$A$9) -> 1.2121212 | BA10: =SUM(BA1*$A$1,BA2*$A$2,BA3*$A$3,BA4*$A$4,BA5*$A$5,BA6*$A$6,BA7*$A$7,BA8*$A$8,BA9*$A$9) -> 1.2929293 | BB10: =SUM(BB1*$A$1,BB2*$A$2,BB3*$A$3,BB4*$A$4,BB5*$A$5,BB6*$A$6,BB7*$A$7,BB8*$A$8,BB9*$A$9) -> 1.3737374
